Workbook

Sheet README
A1: VAACA — Five-year financial model
A2: Built from the Revenue, Business Model & Institutional Sustainability specification.
A4: What this is
B5: A driver-based model: every figure in it comes from a unit count multiplied by a price, or from a
B6: cost driver. Nothing is typed in as a result. Change a count on Customers or a price on Pricing and
B7: the whole model moves, including the monthly cash flow.
A9: What it is not
B10: A forecast. The specification calls its revenue figures planning scenarios, and so are these. The
B11: model's job is to show what would have to be true for each year's target to be met — how many
B12: members, how many delegates, how many engagements — and what it costs to deliver them.
A14: Where to start
B15: 1. Assumptions!B4 — pick Conservative, Base or Aggressive. Everything downstream follows.
B16: 2. Customers — the base-case unit counts. These are the real assumptions in the model.
B17: 3. Pricing — one price per product, each traced to the paragraph of the specification it came from.
B18: 4. Cash Flow Monthly — the number that matters most in year one is the lowest point, not the total.
A20: Colour convention
B21: Blue text is an input you may change. Black is a formula. Green is a link to another sheet.
B22: Yellow fill marks the assumptions that move the answer most.
A24: Currency
B25: All figures are XAF. The XAF is pegged to the euro at 655.957, so divide by 656 for a euro figure.
A27: Three things to read before using the numbers
B28: 1. VAACA has no members today, and both secretariat posts are vacant. Year 1 of this model assumes
B29: 247 paying members, six strategic partners and a 250-delegate forum. That is a standing start.
B30: 2. Four of the ten engines — intelligence, data, platform and most of certification — depend on
B31: platform modules that are not built. Their revenue is zero in Year 1 for that reason.
B32: 3. The model charges nothing for the capital needed to reach break-even. Read the lowest cumulative
B33: cash figure on Cash Flow Monthly as the amount that must be raised before any of this starts.

Sheet Assumptions
A1: Assumptions
A2: Blue cells are inputs. Yellow fill marks the ones that move the answer most.
A4: Scenario | B4: Base | C4: ← pick one; every sheet follows it
A6: Scenario multipliers on unit counts
B7: Conservative | C7: Base | D7: Aggressive | E7: Active
A8: Year 1 | B8: 0.8 | C8: 1 | D8: 1.15 | E8: =INDEX($B8:$D8,MATCH($B$4,$B$7:$D$7,0)) -> 1 | H8: Conservative holds Year 1 nearly flat and slows every later year; Aggressive assumes the
A9: Year 2 | B9: 0.7 | C9: 1 | D9: 1.3 | E9: =INDEX($B9:$D9,MATCH($B$4,$B$7:$D$7,0)) -> 1 | H9: network compounds. Year 1 moves least because its counts are closest to being committed.
A10: Year 3 | B10: 0.62 | C10: 1 | D10: 1.4 | E10: =INDEX($B10:$D10,MATCH($B$4,$B$7:$D$7,0)) -> 1
A11: Year 4 | B11: 0.58 | C11: 1 | D11: 1.45 | E11: =INDEX($B11:$D11,MATCH($B$4,$B$7:$D$7,0)) -> 1
A12: Year 5 | B12: 0.55 | C12: 1 | D12: 1.5 | E12: =INDEX($B12:$D12,MATCH($B$4,$B$7:$D$7,0)) -> 1
A13: Active multiplier by year | B13: =E8 -> 1 | C13: =E9 -> 1 | D13: =E10 -> 1 | E13: =E11 -> 1 | F13: =E12 -> 1
B14: Year 1 | C14: Year 2 | D14: Year 3 | E14: Year 4 | F14: Year 5
A16: Cost drivers
A17: Driver | B17: Unit | C17: Year 1 | D17: Year 2 | E17: Year 3 | F17: Year 4 | G17: Year 5
A18: Education delivery cost | B18: % of education revenue | C18: 0.38 | D18: 0.36 | E18: 0.34 | F18: 0.33 | G18: 0.32
A19: Certification delivery cost | B19: % of certification revenue | C19: 0.4 | D19: 0.35 | E19: 0.3 | F19: 0.28 | G19: 0.26
A20: Events delivery cost | B20: % of events revenue | C20: 0.52 | D20: 0.48 | E20: 0.45 | F20: 0.43 | G20: 0.42
A21: Advisory delivery cost | B21: % of advisory revenue | C21: 0.45 | D21: 0.45 | E21: 0.44 | F21: 0.43 | G21: 0.42
A22: Research production cost | B22: % of research revenue | C22: 0.35 | D22: 0.33 | E22: 0.31 | F22: 0.3 | G22: 0.3
A23: Marketing and outreach | B23: % of total revenue | C23: 0.07 | D23: 0.07 | E23: 0.06 | F23: 0.06 | G23: 0.05
A24: Technology and platform | B24: XAF | C24: 22000000 | D24: 38000000 | E24: 62000000 | F24: 85000000 | G24: 105000000
A25: Legal, audit and compliance | B25: XAF | C25: 14000000 | D25: 20000000 | E25: 30000000 | F25: 40000000 | G25: 50000000
A26: Administration and premises | B26: XAF | C26: 24000000 | D26: 38000000 | E26: 58000000 | F26: 80000000 | G26: 100000000
A27: Travel and representation | B27: XAF | C27: 16000000 | D27: 26000000 | E27: 40000000 | F27: 56000000 | G27: 70000000
A28: National chapters | B28: XAF | C28: 10000000 | D28: 26000000 | E28: 48000000 | F28: 72000000 | G28: 95000000
A31: Working capital
A32: Driver | B32: Unit | C32: Value | D32: Note
A33: Opening cash | B33: XAF | C33: 0 | D33: Founding capital in hand on day one. Zero until it is raised.
A34: Collection lag | B34: months | C34: 1 | D34: Institutional invoices are not paid in the month they are issued.
A35: Employer charges | B35: % of salary | C35: 0.22 | D35: On top of gross salary, applied on the Staffing sheet.
A38: Revenue phasing within the year
A39: The share of each engine's annual revenue that lands in each month. Events are the reason this matters: one forum carries a year of sponsorship.
A40: Engine | B40: M1 | C40: M2 | D40: M3 | E40: M4 | F40: M5 | G40: M6 | H40: M7 | I40: M8 | J40: M9 | K40: M10 | L40: M11 | M40: M12 | N40: Check
A41: Membership | B41: 0.3 | C41: 0.1 | D41: 0.08 | E41: 0.06 | F41: 0.06 | G41: 0.05 | H41: 0.05 | I41: 0.05 | J41: 0.06 | K41: 0.06 | L41: 0.07 | M41: 0.06 | N41: =SUM(B41:M41) -> 1
A42: Strategic partnerships | B42: 0 | C42: 0.35 | D42: 0.1 | E42: 0.05 | F42: 0.05 | G42: 0.05 | H42: 0.25 | I42: 0.05 | J42: 0.03 | K42: 0.03 | L42: 0.02 | M42: 0.02 | N42: =SUM(B42:M42) -> 1
A43: Professional education | B43: 0 | C43: 0.02 | D43: 0.1 | E43: 0.12 | F43: 0.12 | G43: 0.08 | H43: 0.04 | I43: 0.08 | J43: 0.12 | K43: 0.14 | L43: 0.12 | M43: 0.06 | N43: =SUM(B43:M43) -> 1
A44: Certification | B44: 0 | C44: 0 | D44: 0.05 | E44: 0.12 | F44: 0.12 | G44: 0.08 | H44: 0.05 | I44: 0.08 | J44: 0.12 | K44: 0.14 | L44: 0.14 | M44: 0.1 | N44: =SUM(B44:M44) -> 1
A45: Research | B45: 0.04 | C45: 0.06 | D45: 0.08 | E45: 0.08 | F45: 0.1 | G45: 0.1 | H45: 0.08 | I45: 0.08 | J45: 0.1 | K45: 0.1 | L45: 0.1 | M45: 0.08 | N45: =SUM(B45:M45) -> 1
A46: Intelligence | B46: 0.12 | C46: 0.08 | D46: 0.08 | E46: 0.08 | F46: 0.08 | G46: 0.08 | H46: 0.08 | I46: 0.08 | J46: 0.08 | K46: 0.08 | L46: 0.08 | M46: 0.08 | N46: =SUM(B46:M46) -> 1
A47: Events | B47: 0 | C47: 0.02 | D47: 0.04 | E47: 0.06 | F47: 0.08 | G47: 0.14 | H47: 0.2 | I47: 0.12 | J47: 0.28 | K47: 0.04 | L47: 0.02 | M47: 0 | N47: =SUM(B47:M47) -> 1
...

Sheet Pricing
A1: Pricing
A2: One price per product. Every basis cites the paragraph of the specification it came from.
A3: Code | B3: Product | C3: Engine | D3: Price (XAF) | E3: Basis
A4: M1 | B4: Individual member | C4: Membership | D4: 37500 | E4: Mid-point of the 25,000–50,000 band (§6)
A5: M2 | B5: Professional member | C5: Membership | D5: 175000 | E5: Mid-point of 100,000–250,000 (§6)
A6: M3 | B6: SME member | C6: Membership | D6: 375000 | E6: Mid-point of 250,000–500,000 (§6)
A7: M4 | B7: Corporate member | C7: Membership | D7: 1375000 | E7: Mid-point of 750,000–2,000,000 (§6)
A8: M5 | B8: Institutional member | C8: Membership | D8: 3250000 | E8: Mid-point of 1.5M–5M (§6)
A9: M6 | B9: Strategic institutional partner (membership) | C9: Membership | D9: 15000000 | E9: Lower half of 5M–25M (§6)
A10: P1 | B10: Founding partner | C10: Strategic partnerships | D10: 15000000 | E10: Founding tier within the 500,000–100M range (§8)
A11: P2 | B11: Regional strategic partner | C11: Strategic partnerships | D11: 5000000 | E11: Regional tier (§8)
A12: P3 | B12: Programme partner | C12: Strategic partnerships | D12: 1500000 | E12: Programme tier (§8)
A13: E1 | B13: Open-enrolment seat | C13: Professional education | D13: 800000 | E13: Mid-point of 500,000–1.5M per person (§12)
A14: E2 | B14: Corporate cohort | C14: Professional education | D14: 10000000 | E14: Mid-point of 5M–20M per cohort (§12)
A15: E3 | B15: Institutional programme | C15: Professional education | D15: 20000000 | E15: Lower half of 10M–50M+ (§12)
... A38: L2 | B38: Platform enterprise workspace | C38: Platform services | D38: 5000000 | E38: §27 enterprise tier

Sheet Customers
A1: Unit counts
A2: The base case is the real assumption set. The right-hand block applies the scenario.
A3: Code | B3: Product | C3: Engine | D3: Base Year 1 | E3: Base Year 2 | F3: Base Year 3 | G3: Base Year 4 | H3: Base Year 5 | J3: Scenario Year 1 | K3: Scenario Year 2 | L3: Scenario Year 3 | M3: Scenario Year 4 | N3: Scenario Year 5
A4: M1 | B4: Individual member | C4: Membership | D4: 120 | E4: 230 | F4: 430 | G4: 700 | H4: 1050 | J4: =ROUND(D4*Assumptions!$B$13,0) -> 120 | K4: =ROUND(E4*Assumptions!$C$13,0) -> 230 | L4: =ROUND(F4*Assumptions!$D$13,0) -> 430 | M4: =ROUND(G4*Assumptions!$E$13,0) -> 700 | N4: =ROUND(H4*Assumptions!$F$13,0) -> 1050
A5: M2 | B5: Professional member | C5: Membership | D5: 90 | E5: 165 | F5: 290 | G5: 470 | H5: 700 | J5: =ROUND(D5*Assumptions!$B$13,0) -> 90 | K5: =ROUND(E5*Assumptions!$C$13,0) -> 165 | L5: =ROUND(F5*Assumptions!$D$13,0) -> 290 | M5: =ROUND(G5*Assumptions!$E$13,0) -> 470 | N5: =ROUND(H5*Assumptions!$F$13,0) -> 700
A6: M3 | B6: SME member | C6: Membership | D6: 25 | E6: 48 | F6: 88 | G6: 150 | H6: 235 | J6: =ROUND(D6*Assumptions!$B$13,0) -> 25 | K6: =ROUND(E6*Assumptions!$C$13,0) -> 48 | L6: =ROUND(F6*Assumptions!$D$13,0) -> 88 | M6: =ROUND(G6*Assumptions!$E$13,0) -> 150 | N6: =ROUND(H6*Assumptions!$F$13,0) -> 235
A7: M4 | B7: Corporate member | C7: Membership | D7: 10 | E7: 21 | F7: 40 | G7: 66 | H7: 102 | J7: =ROUND(D7*Assumptions!$B$13,0) -> 10 | K7: =ROUND(E7*Assumptions!$C$13,0) -> 21 | L7: =ROUND(F7*Assumptions!$D$13,0) -> 40 | M7: =ROUND(G7*Assumptions!$E$13,0) -> 66 | N7: =ROUND(H7*Assumptions!$F$13,0) -> 102
A8: M5 | B8: Institutional member | C8: Membership | D8: 2 | E8: 5 | F8: 11 | G8: 20 | H8: 32 | J8: =ROUND(D8*Assumptions!$B$13,0) -> 2 | K8: =ROUND(E8*Assumptions!$C$13,0) -> 5 | L8: =ROUND(F8*Assumptions!$D$13,0) -> 11 | M8: =ROUND(G8*Assumptions!$E$13,0) -> 20 | N8: =ROUND(H8*Assumptions!$F$13,0) -> 32
A9: M6 | B9: Strategic institutional partner (membership) | C9: Membership | D9: 0 | E9: 1 | F9: 2 | G9: 4 | H9: 6 | J9: =ROUND(D9*Assumptions!$B$13,0) -> 0 | K9: =ROUND(E9*Assumptions!$C$13,0) -> 1 | L9: =ROUND(F9*Assumptions!$D$13,0) -> 2 | M9: =ROUND(G9*Assumptions!$E$13,0) -> 4 | N9: =ROUND(H9*Assumptions!$F$13,0) -> 6
A10: P1 | B10: Founding partner | C10: Strategic partnerships | D10: 2 | E10: 2 | F10: 4 | G10: 5 | H10: 6 | J10: =ROUND(D10*Assumptions!$B$13,0) -> 2 | K10: =ROUND(E10*Assumptions!$C$13,0) -> 2 | L10: =ROUND(F10*Assumptions!$D$13,0) -> 4 | M10: =ROUND(G10*Assumptions!$E$13,0) -> 5 | N10: =ROUND(H10*Assumptions!$F$13,0) -> 6
A11: P2 | B11: Regional strategic partner | C11: Strategic partnerships | D11: 4 | E11: 6 | F11: 9 | G11: 13 | H11: 16 | J11: =ROUND(D11*Assumptions!$B$13,0) -> 4 | K11: =ROUND(E11*Assumptions!$C$13,0) -> 6 | L11: =ROUND(F11*Assumptions!$D$13,0) -> 9 | M11: =ROUND(G11*Assumptions!$E$13,0) -> 13 | N11: =ROUND(H11*Assumptions!$F$13,0) -> 16
A12: P3 | B12: Programme partner | C12: Strategic partnerships | D12: 0 | E12: 3 | F12: 8 | G12: 15 | H12: 24 | J12: =ROUND(D12*Assumptions!$B$13,0) -> 0 | K12: =ROUND(E12*Assumptions!$C$13,0) -> 3 | L12: =ROUND(F12*Assumptions!$D$13,0) -> 8 | M12: =ROUND(G12*Assumptions!$E$13,0) -> 15 | N12: =ROUND(H12*Assumptions!$F$13,0) -> 24
A13: E1 | B13: Open-enrolment seat | C13: Professional education | D13: 50 | E13: 95 | F13: 135 | G13: 170 | H13: 200 | J13: =ROUND(D13*Assumptions!$B$13,0) -> 50 | K13: =ROUND(E13*Assumptions!$C$13,0) -> 95 | L13: =ROUND(F13*Assumptions!$D$13,0) -> 135 | M13: =ROUND(G13*Assumptions!$E$13,0) -> 170 | N13: =ROUND(H13*Assumptions!$F$13,0) -> 200
A14: E2 | B14: Corporate cohort | C14: Professional education | D14: 2 | E14: 4 | F14: 6 | G14: 8 | H14: 10 | J14: =ROUND(D14*Assumptions!$B$13,0) -> 2 | K14: =ROUND(E14*Assumptions!$C$13,0) -> 4 | L14: =ROUND(F14*Assumptions!$D$13,0) -> 6 | M14: =ROUND(G14*Assumptions!$E$13,0) -> 8 | N14: =ROUND(H14*Assumptions!$F$13,0) -> 10
A15: E3 | B15: Institutional programme | C15: Professional education | D15: 0 | E15: 0 | F15: 1 | G15: 2 | H15: 4 | J15: =ROUND(D15*Assumptions!$B$13,0) -> 0 | K15: =ROUND(E15*Assumptions!$C$13,0) -> 0 | L15: =ROUND(F15*Assumptions!$D$13,0) -> 1 | M15: =ROUND(G15*Assumptions!$E$13,0) -> 2 | N15: =ROUND(H15*Assumptions!$F$13,0) -> 4
... A38: L2 | B38: Platform enterprise workspace | C38: Platform services | D38: 0 | E38: 0 | F38: 2 | G38: 4 | H38: 6 | J38: =ROUND(D38*Assumptions!$B$13,0) -> 0 | K38: =ROUND(E38*Assumptions!$C$13,0) -> 0 | L38: =ROUND(F38*Assumptions!$D$13,0) -> 2 | M38: =ROUND(G38*Assumptions!$E$13,0) -> 4 | N38: =ROUND(H38*Assumptions!$F$13,0) -> 6
B40: Counts are annual: a member counted in Year 2 is a member that year, renewed or new.
B41: Zero in Year 1 means the product does not exist yet — see the README.

Sheet Revenue
A1: Revenue (XAF)
A2: Unit count × price. Nothing here is typed in.
A3: Code | B3: Product | C3: Engine | D3: Year 1 | E3: Year 2 | F3: Year 3 | G3: Year 4 | H3: Year 5 | J3: Delivered by
A4: M1 | B4: Individual member | C4: Membership | D4: =Customers!J4*Pricing!$D$4 -> 4500000 | E4: =Customers!K4*Pricing!$D$4 -> 8625000 | F4: =Customers!L4*Pricing!$D$4 -> 16125000 | G4: =Customers!M4*Pricing!$D$4 -> 26250000 | H4: =Customers!N4*Pricing!$D$4 -> 39375000 | J4: VAACA
A5: M2 | B5: Professional member | C5: Membership | D5: =Customers!J5*Pricing!$D$5 -> 15750000 | E5: =Customers!K5*Pricing!$D$5 -> 28875000 | F5: =Customers!L5*Pricing!$D$5 -> 50750000 | G5: =Customers!M5*Pricing!$D$5 -> 82250000 | H5: =Customers!N5*Pricing!$D$5 -> 122500000 | J5: VAACA
A6: M3 | B6: SME member | C6: Membership | D6: =Customers!J6*Pricing!$D$6 -> 9375000 | E6: =Customers!K6*Pricing!$D$6 -> 18000000 | F6: =Customers!L6*Pricing!$D$6 -> 33000000 | G6: =Customers!M6*Pricing!$D$6 -> 56250000 | H6: =Customers!N6*Pricing!$D$6 -> 88125000 | J6: VAACA
A7: M4 | B7: Corporate member | C7: Membership | D7: =Customers!J7*Pricing!$D$7 -> 13750000 | E7: =Customers!K7*Pricing!$D$7 -> 28875000 | F7: =Customers!L7*Pricing!$D$7 -> 55000000 | G7: =Customers!M7*Pricing!$D$7 -> 90750000 | H7: =Customers!N7*Pricing!$D$7 -> 140250000 | J7: VAACA
A8: M5 | B8: Institutional member | C8: Membership | D8: =Customers!J8*Pricing!$D$8 -> 6500000 | E8: =Customers!K8*Pricing!$D$8 -> 16250000 | F8: =Customers!L8*Pricing!$D$8 -> 35750000 | G8: =Customers!M8*Pricing!$D$8 -> 65000000 | H8: =Customers!N8*Pricing!$D$8 -> 104000000 | J8: VAACA
A9: M6 | B9: Strategic institutional partner (membership) | C9: Membership | D9: =Customers!J9*Pricing!$D$9 -> 0 | E9: =Customers!K9*Pricing!$D$9 -> 15000000 | F9: =Customers!L9*Pricing!$D$9 -> 30000000 | G9: =Customers!M9*Pricing!$D$9 -> 60000000 | H9: =Customers!N9*Pricing!$D$9 -> 90000000 | J9: VAACA
A10: P1 | B10: Founding partner | C10: Strategic partnerships | D10: =Customers!J10*Pricing!$D$10 -> 30000000 | E10: =Customers!K10*Pricing!$D$10 -> 30000000 | F10: =Customers!L10*Pricing!$D$10 -> 60000000 | G10: =Customers!M10*Pricing!$D$10 -> 75000000 | H10: =Customers!N10*Pricing!$D$10 -> 90000000 | J10: VAACA
A11: P2 | B11: Regional strategic partner | C11: Strategic partnerships | D11: =Customers!J11*Pricing!$D$11 -> 20000000 | E11: =Customers!K11*Pricing!$D$11 -> 30000000 | F11: =Customers!L11*Pricing!$D$11 -> 45000000 | G11: =Customers!M11*Pricing!$D$11 -> 65000000 | H11: =Customers!N11*Pricing!$D$11 -> 80000000 | J11: VAACA
A12: P3 | B12: Programme partner | C12: Strategic partnerships | D12: =Customers!J12*Pricing!$D$12 -> 0 | E12: =Customers!K12*Pricing!$D$12 -> 4500000 | F12: =Customers!L12*Pricing!$D$12 -> 12000000 | G12: =Customers!M12*Pricing!$D$12 -> 22500000 | H12: =Customers!N12*Pricing!$D$12 -> 36000000 | J12: VAACA
A13: E1 | B13: Open-enrolment seat | C13: Professional education | D13: =Customers!J13*Pricing!$D$13 -> 40000000 | E13: =Customers!K13*Pricing!$D$13 -> 76000000 | F13: =Customers!L13*Pricing!$D$13 -> 108000000 | G13: =Customers!M13*Pricing!$D$13 -> 136000000 | H13: =Customers!N13*Pricing!$D$13 -> 160000000 | J13: IAFN
A14: E2 | B14: Corporate cohort | C14: Professional education | D14: =Customers!J14*Pricing!$D$14 -> 20000000 | E14: =Customers!K14*Pricing!$D$14 -> 40000000 | F14: =Customers!L14*Pricing!$D$14 -> 60000000 | G14: =Customers!M14*Pricing!$D$14 -> 80000000 | H14: =Customers!N14*Pricing!$D$14 -> 100000000 | J14: IAFN
A15: E3 | B15: Institutional programme | C15: Professional education | D15: =Customers!J15*Pricing!$D$15 -> 0 | E15: =Customers!K15*Pricing!$D$15 -> 0 | F15: =Customers!L15*Pricing!$D$15 -> 20000000 | G15: =Customers!M15*Pricing!$D$15 -> 40000000 | H15: =Customers!N15*Pricing!$D$15 -> 80000000 | J15: IAFN
A16: C1 | B16: Certification candidate (registration, exam, award) | C16: Certification | D16: =Customers!J16*Pricing!$D$16 -> 0 | E16: =Customers!K16*Pricing!$D$16 -> 18000000 | F16: =Customers!L16*Pricing!$D$16 -> 38250000 | G16: =Customers!M16*Pricing!$D$16 -> 60750000 | H16: =Customers!N16*Pricing!$D$16 -> 81000000 | J16: IAFN
A17: C2 | B17: Annual certification renewal | C17: Certification | D17: =Customers!J17*Pricing!$D$17 -> 0 | E17: =Customers!K17*Pricing!$D$17 -> 0 | F17: =Customers!L17*Pricing!$D$17 -> 3600000 | G17: =Customers!M17*Pricing!$D$17 -> 12600000 | H17: =Customers!N17*Pricing!$D$17 -> 36000000 | J17: IAFN
A18: C3 | B18: Corporate certification programme | C18: Certification | D18: =Customers!J18*Pricing!$D$18 -> 0 | E18: =Customers!K18*Pricing!$D$18 -> 0 | F18: =Customers!L18*Pricing!$D$18 -> 6000000 | G18: =Customers!M18*Pricing!$D$18 -> 18000000 | H18: =Customers!N18*Pricing!$D$18 -> 30000000 | J18: IAFN
A19: R1 | B19: Premium report | C19: Research | D19: =Customers!J19*Pricing!$D$19 -> 12000000 | E19: =Customers!K19*Pricing!$D$19 -> 24000000 | F19: =Customers!L19*Pricing!$D$19 -> 42000000 | G19: =Customers!M19*Pricing!$D$19 -> 63000000 | H19: =Customers!N19*Pricing!$D$19 -> 90000000 | J19: VAACA
A20: R2 | B20: Enterprise research licence | C20: Research | D20: =Customers!J20*Pricing!$D$20 -> 7000000 | E20: =Customers!K20*Pricing!$D$20 -> 21000000 | F20: =Customers!L20*Pricing!$D$20 -> 35000000 | G20: =Customers!M20*Pricing!$D$20 -> 56000000 | H20: =Customers!N20*Pricing!$D$20 -> 84000000 | J20: VAACA
A21: R3 | B21: Custom research project | C21: Research | D21: =Customers!J21*Pricing!$D$21 -> 0 | E21: =Customers!K21*Pricing!$D$21 -> 0 | F21: =Customers!L21*Pricing!$D$21 -> 25000000 | G21: =Customers!M21*Pricing!$D$21 -> 50000000 | H21: =Customers!N21*Pricing!$D$21 -> 75000000 | J21: IAFN
A22: I1 | B22: Intelligence — Basic | C22: Intelligence | D22: =Customers!J22*Pricing!$D$22 -> 0 | E22: =Customers!K22*Pricing!$D$22 -> 11250000 | F22: =Customers!L22*Pricing!$D$22 -> 22500000 | G22: =Customers!M22*Pricing!$D$22 -> 36250000 | H22: =Customers!N22*Pricing!$D$22 -> 50000000 | J22: VAACA
A23: I2 | B23: Intelligence — Professional | C23: Intelligence | D23: =Customers!J23*Pricing!$D$23 -> 0 | E23: =Customers!K23*Pricing!$D$23 -> 9750000 | F23: =Customers!L23*Pricing!$D$23 -> 22500000 | G23: =Customers!M23*Pricing!$D$23 -> 41250000 | H23: =Customers!N23*Pricing!$D$23 -> 67500000 | J23: VAACA
A24: I3 | B24: Intelligence — Enterprise | C24: Intelligence | D24: =Customers!J24*Pricing!$D$24 -> 0 | E24: =Customers!K24*Pricing!$D$24 -> 7000000 | F24: =Customers!L24*Pricing!$D$24 -> 21000000 | G24: =Customers!M24*Pricing!$D$24 -> 42000000 | H24: =Customers!N24*Pricing!$D$24 -> 70000000 | J24: VAACA
A25: I4 | B25: Intelligence — Institutional | C25: Intelligence | D25: =Customers!J25*Pricing!$D$25 -> 0 | E25: =Customers!K25*Pricing!$D$25 -> 0 | F25: =Customers!L25*Pricing!$D$25 -> 10000000 | G25: =Customers!M25*Pricing!$D$25 -> 20000000 | H25: =Customers!N25*Pricing!$D$25 -> 40000000 | J25: VAACA
A26: I5 | B26: Intelligence — Strategic | C26: Intelligence | D26: =Customers!J26*Pricing!$D$26 -> 0 | E26: =Customers!K26*Pricing!$D$26 -> 0 | F26: =Customers!L26*Pricing!$D$26 -> 0 | G26: =Customers!M26*Pricing!$D$26 -> 0 | H26: =Customers!N26*Pricing!$D$26 -> 0 | J26: VAACA
A27: V1 | B27: Forum delegate | C27: Events | D27: =Customers!J27*Pricing!$D$27 -> 15000000 | E27: =Customers!K27*Pricing!$D$27 -> 24000000 | F27: =Customers!L27*Pricing!$D$27 -> 36000000 | G27: =Customers!M27*Pricing!$D$27 -> 52800000 | H27: =Customers!N27*Pricing!$D$27 -> 75000000 | J27: VAACA
A28: V2 | B28: Platinum sponsor | C28: Events | D28: =Customers!J28*Pricing!$D$28 -> 10000000 | E28: =Customers!K28*Pricing!$D$28 -> 20000000 | F28: =Customers!L28*Pricing!$D$28 -> 30000000 | G28: =Customers!M28*Pricing!$D$28 -> 50000000 | H28: =Customers!N28*Pricing!$D$28 -> 80000000 | J28: VAACA
A29: V3 | B29: Gold sponsor | C29: Events | D29: =Customers!J29*Pricing!$D$29 -> 15000000 | E29: =Customers!K29*Pricing!$D$29 -> 22500000 | F29: =Customers!L29*Pricing!$D$29 -> 45000000 | G29: =Customers!M29*Pricing!$D$29 -> 75000000 | H29: =Customers!N29*Pricing!$D$29 -> 120000000 | J29: VAACA
A30: V4 | B30: Silver sponsor | C30: Events | D30: =Customers!J30*Pricing!$D$30 -> 0 | E30: =Customers!K30*Pricing!$D$30 -> 9000000 | F30: =Customers!L30*Pricing!$D$30 -> 24000000 | G30: =Customers!M30*Pricing!$D$30 -> 45000000 | H30: =Customers!N30*Pricing!$D$30 -> 66000000 | J30: VAACA
A31: A1 | B31: Advisory — diagnostic | C31: Advisory | D31: =Customers!J31*Pricing!$D$31 -> 12000000 | E31: =Customers!K31*Pricing!$D$31 -> 20000000 | F31: =Customers!L31*Pricing!$D$31 -> 40000000 | G31: =Customers!M31*Pricing!$D$31 -> 60000000 | H31: =Customers!N31*Pricing!$D$31 -> 80000000 | J31: IAFN
A32: A2 | B32: Advisory — strategic engagement | C32: Advisory | D32: =Customers!J32*Pricing!$D$32 -> 18000000 | E32: =Customers!K32*Pricing!$D$32 -> 36000000 | F32: =Customers!L32*Pricing!$D$32 -> 72000000 | G32: =Customers!M32*Pricing!$D$32 -> 126000000 | H32: =Customers!N32*Pricing!$D$32 -> 180000000 | J32: IAFN
A33: A3 | B33: Advisory — institutional transformation | C33: Advisory | D33: =Customers!J33*Pricing!$D$33 -> 0 | E33: =Customers!K33*Pricing!$D$33 -> 0 | F33: =Customers!L33*Pricing!$D$33 -> 0 | G33: =Customers!M33*Pricing!$D$33 -> 80000000 | H33: =Customers!N33*Pricing!$D$33 -> 80000000 | J33: IAFN
A34: D1 | B34: Database subscription | C34: Data products | D34: =Customers!J34*Pricing!$D$34 -> 0 | E34: =Customers!K34*Pricing!$D$34 -> 6000000 | F34: =Customers!L34*Pricing!$D$34 -> 18000000 | G34: =Customers!M34*Pricing!$D$34 -> 33600000 | H34: =Customers!N34*Pricing!$D$34 -> 54000000 | J34: VAACA
A35: D2 | B35: Enterprise data licence | C35: Data products | D35: =Customers!J35*Pricing!$D$35 -> 0 | E35: =Customers!K35*Pricing!$D$35 -> 0 | F35: =Customers!L35*Pricing!$D$35 -> 16000000 | G35: =Customers!M35*Pricing!$D$35 -> 32000000 | H35: =Customers!N35*Pricing!$D$35 -> 48000000 | J35: VAACA
A36: D3 | B36: API / data feed | C36: Data products | D36: =Customers!J36*Pricing!$D$36 -> 0 | E36: =Customers!K36*Pricing!$D$36 -> 0 | F36: =Customers!L36*Pricing!$D$36 -> 0 | G36: =Customers!M36*Pricing!$D$36 -> 15000000 | H36: =Customers!N36*Pricing!$D$36 -> 30000000 | J36: VAACA
A37: L1 | B37: Platform premium seat | C37: Platform services | D37: =Customers!J37*Pricing!$D$37 -> 0 | E37: =Customers!K37*Pricing!$D$37 -> 7500000 | F37: =Customers!L37*Pricing!$D$37 -> 16500000 | G37: =Customers!M37*Pricing!$D$37 -> 30000000 | H37: =Customers!N37*Pricing!$D$37 -> 45000000 | J37: VAACA
A38: L2 | B38: Platform enterprise workspace | C38: Platform services | D38: =Customers!J38*Pricing!$D$38 -> 0 | E38: =Customers!K38*Pricing!$D$38 -> 0 | F38: =Customers!L38*Pricing!$D$38 -> 10000000 | G38: =Customers!M38*Pricing!$D$38 -> 20000000 | H38: =Customers!N38*Pricing!$D$38 -> 30000000 | J38: VAACA
A39: By engine
A40: Engine | D40: Year 1 | E40: Year 2 | F40: Year 3 | G40: Year 4 | H40: Year 5
...

Sheet Staffing
A1: Staffing
A2: Headcount by role. Fully loaded cost adds employer charges from the Assumptions sheet.
A3: Role | B3: Gross annual salary (XAF) | C3: Heads Year 1 | D3: Heads Year 2 | E3: Heads Year 3 | F3: Heads Year 4 | G3: Heads Year 5 | I3: Cost Year 1 | J3: Cost Year 2 | K3: Cost Year 3 | L3: Cost Year 4 | M3: Cost Year 5 | O3: Entity
A4: Secretary General | B4: 21600000 | C4: 1 | D4: 1 | E4: 1 | F4: 1 | G4: 1 | I4: =C4*$B4*(1+Assumptions!$C$35) -> 26352000 | J4: =D4*$B4*(1+Assumptions!$C$35) -> 26352000 | K4: =E4*$B4*(1+Assumptions!$C$35) -> 26352000 | L4: =F4*$B4*(1+Assumptions!$C$35) -> 26352000 | M4: =G4*$B4*(1+Assumptions!$C$35) -> 26352000 | O4: VAACA
A5: Standards & Assessment Officer | B5: 15600000 | C5: 1 | D5: 1 | E5: 1 | F5: 1 | G5: 1 | I5: =C5*$B5*(1+Assumptions!$C$35) -> 19032000 | J5: =D5*$B5*(1+Assumptions!$C$35) -> 19032000 | K5: =E5*$B5*(1+Assumptions!$C$35) -> 19032000 | L5: =F5*$B5*(1+Assumptions!$C$35) -> 19032000 | M5: =G5*$B5*(1+Assumptions!$C$35) -> 19032000 | O5: VAACA
A6: Research lead | B6: 15600000 | C6: 1 | D6: 1 | E6: 1 | F6: 2 | G6: 2 | I6: =C6*$B6*(1+Assumptions!$C$35) -> 19032000 | J6: =D6*$B6*(1+Assumptions!$C$35) -> 19032000 | K6: =E6*$B6*(1+Assumptions!$C$35) -> 19032000 | L6: =F6*$B6*(1+Assumptions!$C$35) -> 38064000 | M6: =G6*$B6*(1+Assumptions!$C$35) -> 38064000 | O6: VAACA
A7: Education lead | B7: 14400000 | C7: 1 | D7: 1 | E7: 1 | F7: 1 | G7: 2 | I7: =C7*$B7*(1+Assumptions!$C$35) -> 17568000 | J7: =D7*$B7*(1+Assumptions!$C$35) -> 17568000 | K7: =E7*$B7*(1+Assumptions!$C$35) -> 17568000 | L7: =F7*$B7*(1+Assumptions!$C$35) -> 17568000 | M7: =G7*$B7*(1+Assumptions!$C$35) -> 35136000 | O7: IAFN
A8: Membership & partnerships lead | B8: 14400000 | C8: 1 | D8: 1 | E8: 2 | F8: 2 | G8: 3 | I8: =C8*$B8*(1+Assumptions!$C$35) -> 17568000 | J8: =D8*$B8*(1+Assumptions!$C$35) -> 17568000 | K8: =E8*$B8*(1+Assumptions!$C$35) -> 35136000 | L8: =F8*$B8*(1+Assumptions!$C$35) -> 35136000 | M8: =G8*$B8*(1+Assumptions!$C$35) -> 52704000 | O8: VAACA
A9: Finance & administration | B9: 10800000 | C9: 1 | D9: 1 | E9: 2 | F9: 2 | G9: 3 | I9: =C9*$B9*(1+Assumptions!$C$35) -> 13176000 | J9: =D9*$B9*(1+Assumptions!$C$35) -> 13176000 | K9: =E9*$B9*(1+Assumptions!$C$35) -> 26352000 | L9: =F9*$B9*(1+Assumptions!$C$35) -> 26352000 | M9: =G9*$B9*(1+Assumptions!$C$35) -> 39528000 | O9: VAACA
A10: Intelligence lead | B10: 15600000 | C10: 0 | D10: 1 | E10: 1 | F10: 1 | G10: 2 | I10: =C10*$B10*(1+Assumptions!$C$35) -> 0 | J10: =D10*$B10*(1+Assumptions!$C$35) -> 19032000 | K10: =E10*$B10*(1+Assumptions!$C$35) -> 19032000 | L10: =F10*$B10*(1+Assumptions!$C$35) -> 19032000 | M10: =G10*$B10*(1+Assumptions!$C$35) -> 38064000 | O10: VAACA
A11: Events manager | B11: 10800000 | C11: 0 | D11: 1 | E11: 1 | F11: 2 | G11: 2 | I11: =C11*$B11*(1+Assumptions!$C$35) -> 0 | J11: =D11*$B11*(1+Assumptions!$C$35) -> 13176000 | K11: =E11*$B11*(1+Assumptions!$C$35) -> 13176000 | L11: =F11*$B11*(1+Assumptions!$C$35) -> 26352000 | M11: =G11*$B11*(1+Assumptions!$C$35) -> 26352000 | O11: VAACA
A12: Research analyst | B12: 8400000 | C12: 0 | D12: 1 | E12: 3 | F12: 5 | G12: 7 | I12: =C12*$B12*(1+Assumptions!$C$35) -> 0 | J12: =D12*$B12*(1+Assumptions!$C$35) -> 10248000 | K12: =E12*$B12*(1+Assumptions!$C$35) -> 30744000 | L12: =F12*$B12*(1+Assumptions!$C$35) -> 51240000 | M12: =G12*$B12*(1+Assumptions!$C$35) -> 71736000 | O12: VAACA
A13: Platform engineer | B13: 13200000 | C13: 0 | D13: 1 | E13: 2 | F13: 3 | G13: 4 | I13: =C13*$B13*(1+Assumptions!$C$35) -> 0 | J13: =D13*$B13*(1+Assumptions!$C$35) -> 16104000 | K13: =E13*$B13*(1+Assumptions!$C$35) -> 32208000 | L13: =F13*$B13*(1+Assumptions!$C$35) -> 48312000 | M13: =G13*$B13*(1+Assumptions!$C$35) -> 64416000 | O13: VAACA
A14: Programme officer | B14: 8400000 | C14: 0 | D14: 1 | E14: 2 | F14: 4 | G14: 6 | I14: =C14*$B14*(1+Assumptions!$C$35) -> 0 | J14: =D14*$B14*(1+Assumptions!$C$35) -> 10248000 | K14: =E14*$B14*(1+Assumptions!$C$35) -> 20496000 | L14: =F14*$B14*(1+Assumptions!$C$35) -> 40992000 | M14: =G14*$B14*(1+Assumptions!$C$35) -> 61488000 | O14: VAACA
A15: Chapter coordinator | B15: 7200000 | C15: 0 | D15: 0 | E15: 2 | F15: 4 | G15: 6 | I15: =C15*$B15*(1+Assumptions!$C$35) -> 0 | J15: =D15*$B15*(1+Assumptions!$C$35) -> 0 | K15: =E15*$B15*(1+Assumptions!$C$35) -> 17568000 | L15: =F15*$B15*(1+Assumptions!$C$35) -> 35136000 | M15: =G15*$B15*(1+Assumptions!$C$35) -> 52704000 | O15: VAACA
A17: Total headcount | B17: Personnel cost → | C17: =SUM(C4:C15) -> 6 | D17: =SUM(D4:D15) -> 11 | E17: =SUM(E4:E15) -> 19 | F17: =SUM(F4:F15) -> 28 | G17: =SUM(G4:G15) -> 39 | I17: =SUM(I4:I15) -> 112728000 | J17: =SUM(J4:J15) -> 181536000 | K17: =SUM(K4:K15) -> 276696000 | L17: =SUM(L4:L15) -> 383568000 | M17: =SUM(M4:M15) -> 525576000
A19: Salaries are planning figures for Yaoundé, not offers. Both Year 1 posts are currently vacant.
A20: IAFN's own staffing is outside this model. Only the post VAACA would otherwise carry and no longer needs is marked — the education lead.

Sheet Costs
A1: Costs (XAF)
A2: Delivery costs scale with the revenue they deliver; the rest are planned directly.
A3: Cost line | B3: Driver | C3: Year 1 | D3: Year 2 | E3: Year 3 | F3: Year 4 | G3: Year 5
A4: Personnel | B4: Staffing sheet | C4: =Staffing!I$17 -> 112728000 | D4: =Staffing!J$17 -> 181536000 | E4: =Staffing!K$17 -> 276696000 | F4: =Staffing!L$17 -> 383568000 | G4: =Staffing!M$17 -> 525576000
A5: Education delivery | B5: % of education revenue | C5: =Assumptions!C$18*Revenue!D$43 -> 22800000 | D5: =Assumptions!D$18*Revenue!E$43 -> 41760000 | E5: =Assumptions!E$18*Revenue!F$43 -> 63920000 | F5: =Assumptions!F$18*Revenue!G$43 -> 84480000 | G5: =Assumptions!G$18*Revenue!H$43 -> 108800000
A6: Certification delivery | B6: % of certification revenue | C6: =Assumptions!C$19*Revenue!D$44 -> 0 | D6: =Assumptions!D$19*Revenue!E$44 -> 6300000 | E6: =Assumptions!E$19*Revenue!F$44 -> 14355000 | F6: =Assumptions!F$19*Revenue!G$44 -> 25578000 | G6: =Assumptions!G$19*Revenue!H$44 -> 38220000
A7: Events delivery | B7: % of events revenue | C7: =Assumptions!C$20*Revenue!D$47 -> 20800000 | D7: =Assumptions!D$20*Revenue!E$47 -> 36240000 | E7: =Assumptions!E$20*Revenue!F$47 -> 60750000 | F7: =Assumptions!F$20*Revenue!G$47 -> 95804000 | G7: =Assumptions!G$20*Revenue!H$47 -> 143220000
A8: Advisory delivery | B8: % of advisory revenue | C8: =Assumptions!C$21*Revenue!D$48 -> 13500000 | D8: =Assumptions!D$21*Revenue!E$48 -> 25200000 | E8: =Assumptions!E$21*Revenue!F$48 -> 49280000 | F8: =Assumptions!F$21*Revenue!G$48 -> 114380000 | G8: =Assumptions!G$21*Revenue!H$48 -> 142800000
A9: Research production | B9: % of research revenue | C9: =Assumptions!C$22*Revenue!D$45 -> 6650000 | D9: =Assumptions!D$22*Revenue!E$45 -> 14850000 | E9: =Assumptions!E$22*Revenue!F$45 -> 31620000 | F9: =Assumptions!F$22*Revenue!G$45 -> 50700000 | G9: =Assumptions!G$22*Revenue!H$45 -> 74700000
A10: Marketing and outreach | B10: % of total revenue | C10: =Assumptions!C$23*Revenue!D$52 -> 17421250 | D10: =Assumptions!D$23*Revenue!E$52 -> 37248750 | E10: =Assumptions!E$23*Revenue!F$52 -> 63538500 | F10: =Assumptions!F$23*Revenue!G$52 -> 109095000 | G10: =Assumptions!G$23*Revenue!H$52 -> 132087500
A11: Technology and platform | B11: planned | C11: =Assumptions!C$24 -> 22000000 | D11: =Assumptions!D$24 -> 38000000 | E11: =Assumptions!E$24 -> 62000000 | F11: =Assumptions!F$24 -> 85000000 | G11: =Assumptions!G$24 -> 105000000
A12: Legal, audit and compliance | B12: planned | C12: =Assumptions!C$25 -> 14000000 | D12: =Assumptions!D$25 -> 20000000 | E12: =Assumptions!E$25 -> 30000000 | F12: =Assumptions!F$25 -> 40000000 | G12: =Assumptions!G$25 -> 50000000
A13: Administration and premises | B13: planned | C13: =Assumptions!C$26 -> 24000000 | D13: =Assumptions!D$26 -> 38000000 | E13: =Assumptions!E$26 -> 58000000 | F13: =Assumptions!F$26 -> 80000000 | G13: =Assumptions!G$26 -> 100000000
A14: Travel and representation | B14: planned | C14: =Assumptions!C$27 -> 16000000 | D14: =Assumptions!D$27 -> 26000000 | E14: =Assumptions!E$27 -> 40000000 | F14: =Assumptions!F$27 -> 56000000 | G14: =Assumptions!G$27 -> 70000000
A15: National chapters | B15: planned | C15: =Assumptions!C$28 -> 10000000 | D15: =Assumptions!D$28 -> 26000000 | E15: =Assumptions!E$28 -> 48000000 | F15: =Assumptions!F$28 -> 72000000 | G15: =Assumptions!G$28 -> 95000000
A17: Total costs | C17: =SUM(C4:C15) -> 279899250 | D17: =SUM(D4:D15) -> 491134750 | E17: =SUM(E4:E15) -> 798159500 | F17: =SUM(F4:F15) -> 1196605000 | G17: =SUM(G4:G15) -> 1585403500
A18: of which direct delivery | C18: =SUM(C5:C9) -> 63750000 | D18: =SUM(D5:D9) -> 124350000 | E18: =SUM(E5:E9) -> 219925000 | F18: =SUM(F5:F9) -> 370942000 | G18: =SUM(G5:G9) -> 507740000

Sheet P&L
A1: Operating result (XAF)
A2: Revenue, what it costs to deliver, and what is left to run the institution.
C3: Year 1 | D3: Year 2 | E3: Year 3 | F3: Year 4 | G3: Year 5
A4: Revenue | C4: =Revenue!D$52 -> 248875000 | D4: =Revenue!E$52 -> 532125000 | E4: =Revenue!F$52 -> 1058975000 | F4: =Revenue!G$52 -> 1818250000 | G4: =Revenue!H$52 -> 2641750000
A5: Direct delivery cost | C5: =-Costs!C$18 -> -63750000 | D5: =-Costs!D$18 -> -124350000 | E5: =-Costs!E$18 -> -219925000 | F5: =-Costs!F$18 -> -370942000 | G5: =-Costs!G$18 -> -507740000
A6: Gross surplus | C6: =C4+C5 -> 185125000 | D6: =D4+D5 -> 407775000 | E6: =E4+E5 -> 839050000 | F6: =F4+F5 -> 1447308000 | G6: =G4+G5 -> 2134010000
A7: Gross margin | C7: =IF(C4=0,0,C6/C4) -> 0.74384731 | D7: =IF(D4=0,0,D6/D4) -> 0.76631431 | E7: =IF(E4=0,0,E6/E4) -> 0.79232276 | F7: =IF(F4=0,0,F6/F4) -> 0.79598955 | G7: =IF(G4=0,0,G6/G4) -> 0.80780165
A9: Personnel | C9: =-Costs!C$4 -> -112728000 | D9: =-Costs!D$4 -> -181536000 | E9: =-Costs!E$4 -> -276696000 | F9: =-Costs!F$4 -> -383568000 | G9: =-Costs!G$4 -> -525576000
A10: Other operating costs | C10: =-(Costs!C$17-Costs!C$18-Costs!C$4) -> -103421250 | D10: =-(Costs!D$17-Costs!D$18-Costs!D$4) -> -185248750 | E10: =-(Costs!E$17-Costs!E$18-Costs!E$4) -> -301538500 | F10: =-(Costs!F$17-Costs!F$18-Costs!F$4) -> -442095000 | G10: =-(Costs!G$17-Costs!G$18-Costs!G$4) -> -552087500
A11: Operating surplus | C11: =C6+C9+C10 -> -31024250 | D11: =D6+D9+D10 -> 40990250 | E11: =E6+E9+E10 -> 260815500 | F11: =F6+F9+F10 -> 621645000 | G11: =G6+G9+G10 -> 1056346500
A12: Operating margin | C12: =IF(C4=0,0,C11/C4) -> -0.12465796 | D12: =IF(D4=0,0,D11/D4) -> 0.077031243 | E12: =IF(E4=0,0,E11/E4) -> 0.24629052 | F12: =IF(F4=0,0,F11/F4) -> 0.34189193 | G12: =IF(G4=0,0,G11/G4) -> 0.39986619
A14: Recurring revenue | C14: =Revenue!D$41+Revenue!D$46+Revenue!D$49+Revenue!D$50 -> 49875000 | D14: =Revenue!E$41+Revenue!E$46+Revenue!E$49+Revenue!E$50 -> 157125000 | E14: =Revenue!F$41+Revenue!F$46+Revenue!F$49+Revenue!F$50 -> 357125000 | F14: =Revenue!G$41+Revenue!G$46+Revenue!G$49+Revenue!G$50 -> 650600000 | G14: =Revenue!H$41+Revenue!H$46+Revenue!H$49+Revenue!H$50 -> 1018750000
A15: Recurring share of revenue | C15: =IF(C4=0,0,C14/C4) -> 0.20040181 | D15: =IF(D4=0,0,D14/D4) -> 0.29527837 | E15: =IF(E4=0,0,E14/E4) -> 0.33723648 | F15: =IF(F4=0,0,F14/F4) -> 0.35781658 | G15: =IF(G4=0,0,G14/G4) -> 0.38563452
A16: Revenue per employee | C16: =IF(Staffing!C$17=0,0,C4/Staffing!C$17) -> 41479167 | D16: =IF(Staffing!D$17=0,0,D4/Staffing!D$17) -> 48375000 | E16: =IF(Staffing!E$17=0,0,E4/Staffing!E$17) -> 55735526 | F16: =IF(Staffing!F$17=0,0,F4/Staffing!F$17) -> 64937500 | G16: =IF(Staffing!G$17=0,0,G4/Staffing!G$17) -> 67737179
A18: Public-interest reinvestment
A19: Reinvested share of surplus | C19: 0 | D19: 0.4 | E19: 0.55 | F19: 0.6 | G19: 0.6
A20: Reinvestment in public-interest programmes | C20: =-MAX(0,C11)*C19 -> 0 | D20: =-MAX(0,D11)*D19 -> -16396100 | E20: =-MAX(0,E11)*E19 -> -143448525 | F20: =-MAX(0,F11)*F19 -> -372987000 | G20: =-MAX(0,G11)*G19 -> -633807900
A21: Result after reinvestment | C21: =C11+C20 -> -31024250 | D21: =D11+D20 -> 24594150 | E21: =E11+E20 -> 117366975 | F21: =F11+F20 -> 248658000 | G21: =G11+G20 -> 422538600
A23: A 40% operating surplus is not a target. For an institution of this kind it is headroom, and §38 and §81 say what it is for: subsidised civil-society and student membership, scholarships, financial-literacy and consumer-protection programmes, and the research that nobody will sponsor. Left unspent it would be a signal that the institution is under-investing in the public-interest half of its mandate.

Sheet Cash Flow Monthly
A1: Monthly cash flow (XAF)
A2: Sixty months. The figure that matters is the lowest cumulative balance, not the total.
A4: Month | B4: 1 | C4: 2 | D4: 3 | E4: 4 | F4: 5 | G4: 6 | H4: 7 | I4: 8 | J4: 9 | K4: 10 | L4: 11 | M4: 12 | N4: 13 | O4: 14 | P4: 15 | Q4: 16 | R4: 17 | S4: 18 | T4: 19 | U4: 20 | V4: 21 | W4: 22 | X4: 23 | Y4: 24 | Z4: 25 | AA4: 26 | AB4: 27 | AC4: 28 | AD4: 29 | AE4: 30 | AF4: 31 | AG4: 32 | AH4: 33 | AI4: 34 | AJ4: 35 | AK4: 36 | AL4: 37 | AM4: 38 | AN4: 39 | AO4: 40 | AP4: 41 | AQ4: 42 | AR4: 43 | AS4: 44 | AT4: 45 | AU4: 46 | AV4: 47 | AW4: 48 | AX4: 49 | AY4: 50 | AZ4: 51 | BA4: 52 | BB4: 53 | BC4: 54 | BD4: 55 | BE4: 56 | BF4: 57 | BG4: 58 | BH4: 59 | BI4: 60
A5: Year | B5: =ROUNDUP(B4/12,0) -> 1 | C5: =ROUNDUP(C4/12,0) -> 1 | D5: =ROUNDUP(D4/12,0) -> 1 | E5: =ROUNDUP(E4/12,0) -> 1 | F5: =ROUNDUP(F4/12,0) -> 1 | G5: =ROUNDUP(G4/12,0) -> 1 | H5: =ROUNDUP(H4/12,0) -> 1 | I5: =ROUNDUP(I4/12,0) -> 1 | ... BI5: =ROUNDUP(BI4/12,0) -> 5
A6: Month of year | B6: =B4-12*(B5-1) -> 1 | C6: =C4-12*(C5-1) -> 2 | D6: =D4-12*(D5-1) -> 3 | E6: =E4-12*(E5-1) -> 4 | F6: =F4-12*(F5-1) -> 5 | G6: =G4-12*(G5-1) -> 6 | H6: =H4-12*(H5-1) -> 7 | I6: =I4-12*(I5-1) -> 8 | ... BI6: =BI4-12*(BI5-1) -> 12
A8: Revenue earned
A9: Membership | B9: =INDEX(Revenue!$D$41:$H$41,1,B$5)*INDEX(Assumptions!$B$41:$M$41,1,B$6) -> 14962500 | C9: =INDEX(Revenue!$D$41:$H$41,1,C$5)*INDEX(Assumptions!$B$41:$M$41,1,C$6) -> 4987500 | D9: =INDEX(Revenue!$D$41:$H$41,1,D$5)*INDEX(Assumptions!$B$41:$M$41,1,D$6) -> 3990000 | E9: =INDEX(Revenue!$D$41:$H$41,1,E$5)*INDEX(Assumptions!$B$41:$M$41,1,E$6) -> 2992500 | F9: =INDEX(Revenue!$D$41:$H$41,1,F$5)*INDEX(Assumptions!$B$41:$M$41,1,F$6) -> 2992500 | G9: =INDEX(Revenue!$D$41:$H$41,1,G$5)*INDEX(Assumptions!$B$41:$M$41,1,G$6) -> 2493750 | H9: =INDEX(Revenue!$D$41:$H$41,1,H$5)*INDEX(Assumptions!$B$41:$M$41,1,H$6) -> 2493750 | I9: =INDEX(Revenue!$D$41:$H$41,1,I$5)*INDEX(Assumptions!$B$41:$M$41,1,I$6) -> 2493750 | ... BI9: =INDEX(Revenue!$D$41:$H$41,1,BI$5)*INDEX(Assumptions!$B$41:$M$41,1,BI$6) -> 35055000
A10: Strategic partnerships | B10: =INDEX(Revenue!$D$42:$H$42,1,B$5)*INDEX(Assumptions!$B$42:$M$42,1,B$6) -> 0 | C10: =INDEX(Revenue!$D$42:$H$42,1,C$5)*INDEX(Assumptions!$B$42:$M$42,1,C$6) -> 17500000 | D10: =INDEX(Revenue!$D$42:$H$42,1,D$5)*INDEX(Assumptions!$B$42:$M$42,1,D$6) -> 5000000 | E10: =INDEX(Revenue!$D$42:$H$42,1,E$5)*INDEX(Assumptions!$B$42:$M$42,1,E$6) -> 2500000 | F10: =INDEX(Revenue!$D$42:$H$42,1,F$5)*INDEX(Assumptions!$B$42:$M$42,1,F$6) -> 2500000 | G10: =INDEX(Revenue!$D$42:$H$42,1,G$5)*INDEX(Assumptions!$B$42:$M$42,1,G$6) -> 2500000 | H10: =INDEX(Revenue!$D$42:$H$42,1,H$5)*INDEX(Assumptions!$B$42:$M$42,1,H$6) -> 12500000 | I10: =INDEX(Revenue!$D$42:$H$42,1,I$5)*INDEX(Assumptions!$B$42:$M$42,1,I$6) -> 2500000 | ... BI10: =INDEX(Revenue!$D$42:$H$42,1,BI$5)*INDEX(Assumptions!$B$42:$M$42,1,BI$6) -> 4120000
A11: Professional education | B11: =INDEX(Revenue!$D$43:$H$43,1,B$5)*INDEX(Assumptions!$B$43:$M$43,1,B$6) -> 0 | C11: =INDEX(Revenue!$D$43:$H$43,1,C$5)*INDEX(Assumptions!$B$43:$M$43,1,C$6) -> 1200000 | D11: =INDEX(Revenue!$D$43:$H$43,1,D$5)*INDEX(Assumptions!$B$43:$M$43,1,D$6) -> 6000000 | E11: =INDEX(Revenue!$D$43:$H$43,1,E$5)*INDEX(Assumptions!$B$43:$M$43,1,E$6) -> 7200000 | F11: =INDEX(Revenue!$D$43:$H$43,1,F$5)*INDEX(Assumptions!$B$43:$M$43,1,F$6) -> 7200000 | G11: =INDEX(Revenue!$D$43:$H$43,1,G$5)*INDEX(Assumptions!$B$43:$M$43,1,G$6) -> 4800000 | H11: =INDEX(Revenue!$D$43:$H$43,1,H$5)*INDEX(Assumptions!$B$43:$M$43,1,H$6) -> 2400000 | I11: =INDEX(Revenue!$D$43:$H$43,1,I$5)*INDEX(Assumptions!$B$43:$M$43,1,I$6) -> 4800000 | ... BI11: =INDEX(Revenue!$D$43:$H$43,1,BI$5)*INDEX(Assumptions!$B$43:$M$43,1,BI$6) -> 20400000
A12: Certification | B12: =INDEX(Revenue!$D$44:$H$44,1,B$5)*INDEX(Assumptions!$B$44:$M$44,1,B$6) -> 0 | C12: =INDEX(Revenue!$D$44:$H$44,1,C$5)*INDEX(Assumptions!$B$44:$M$44,1,C$6) -> 0 | D12: =INDEX(Revenue!$D$44:$H$44,1,D$5)*INDEX(Assumptions!$B$44:$M$44,1,D$6) -> 0 | E12: =INDEX(Revenue!$D$44:$H$44,1,E$5)*INDEX(Assumptions!$B$44:$M$44,1,E$6) -> 0 | F12: =INDEX(Revenue!$D$44:$H$44,1,F$5)*INDEX(Assumptions!$B$44:$M$44,1,F$6) -> 0 | G12: =INDEX(Revenue!$D$44:$H$44,1,G$5)*INDEX(Assumptions!$B$44:$M$44,1,G$6) -> 0 | H12: =INDEX(Revenue!$D$44:$H$44,1,H$5)*INDEX(Assumptions!$B$44:$M$44,1,H$6) -> 0 | I12: =INDEX(Revenue!$D$44:$H$44,1,I$5)*INDEX(Assumptions!$B$44:$M$44,1,I$6) -> 0 | ... BI12: =INDEX(Revenue!$D$44:$H$44,1,BI$5)*INDEX(Assumptions!$B$44:$M$44,1,BI$6) -> 14700000
A13: Research | B13: =INDEX(Revenue!$D$45:$H$45,1,B$5)*INDEX(Assumptions!$B$45:$M$45,1,B$6) -> 760000 | C13: =INDEX(Revenue!$D$45:$H$45,1,C$5)*INDEX(Assumptions!$B$45:$M$45,1,C$6) -> 1140000 | D13: =INDEX(Revenue!$D$45:$H$45,1,D$5)*INDEX(Assumptions!$B$45:$M$45,1,D$6) -> 1520000 | E13: =INDEX(Revenue!$D$45:$H$45,1,E$5)*INDEX(Assumptions!$B$45:$M$45,1,E$6) -> 1520000 | F13: =INDEX(Revenue!$D$45:$H$45,1,F$5)*INDEX(Assumptions!$B$45:$M$45,1,F$6) -> 1900000 | G13: =INDEX(Revenue!$D$45:$H$45,1,G$5)*INDEX(Assumptions!$B$45:$M$45,1,G$6) -> 1900000 | H13: =INDEX(Revenue!$D$45:$H$45,1,H$5)*INDEX(Assumptions!$B$45:$M$45,1,H$6) -> 1520000 | I13: =INDEX(Revenue!$D$45:$H$45,1,I$5)*INDEX(Assumptions!$B$45:$M$45,1,I$6) -> 1520000 | ... BI13: =INDEX(Revenue!$D$45:$H$45,1,BI$5)*INDEX(Assumptions!$B$45:$M$45,1,BI$6) -> 19920000
A14: Intelligence | B14: =INDEX(Revenue!$D$46:$H$46,1,B$5)*INDEX(Assumptions!$B$46:$M$46,1,B$6) -> 0 | C14: =INDEX(Revenue!$D$46:$H$46,1,C$5)*INDEX(Assumptions!$B$46:$M$46,1,C$6) -> 0 | D14: =INDEX(Revenue!$D$46:$H$46,1,D$5)*INDEX(Assumptions!$B$46:$M$46,1,D$6) -> 0 | E14: =INDEX(Revenue!$D$46:$H$46,1,E$5)*INDEX(Assumptions!$B$46:$M$46,1,E$6) -> 0 | F14: =INDEX(Revenue!$D$46:$H$46,1,F$5)*INDEX(Assumptions!$B$46:$M$46,1,F$6) -> 0 | G14: =INDEX(Revenue!$D$46:$H$46,1,G$5)*INDEX(Assumptions!$B$46:$M$46,1,G$6) -> 0 | H14: =INDEX(Revenue!$D$46:$H$46,1,H$5)*INDEX(Assumptions!$B$46:$M$46,1,H$6) -> 0 | I14: =INDEX(Revenue!$D$46:$H$46,1,I$5)*INDEX(Assumptions!$B$46:$M$46,1,I$6) -> 0 | ... BI14: =INDEX(Revenue!$D$46:$H$46,1,BI$5)*INDEX(Assumptions!$B$46:$M$46,1,BI$6) -> 18200000
A15: Events | B15: =INDEX(Revenue!$D$47:$H$47,1,B$5)*INDEX(Assumptions!$B$47:$M$47,1,B$6) -> 0 | C15: =INDEX(Revenue!$D$47:$H$47,1,C$5)*INDEX(Assumptions!$B$47:$M$47,1,C$6) -> 800000 | D15: =INDEX(Revenue!$D$47:$H$47,1,D$5)*INDEX(Assumptions!$B$47:$M$47,1,D$6) -> 1600000 | E15: =INDEX(Revenue!$D$47:$H$47,1,E$5)*INDEX(Assumptions!$B$47:$M$47,1,E$6) -> 2400000 | F15: =INDEX(Revenue!$D$47:$H$47,1,F$5)*INDEX(Assumptions!$B$47:$M$47,1,F$6) -> 3200000 | G15: =INDEX(Revenue!$D$47:$H$47,1,G$5)*INDEX(Assumptions!$B$47:$M$47,1,G$6) -> 5600000 | H15: =INDEX(Revenue!$D$47:$H$47,1,H$5)*INDEX(Assumptions!$B$47:$M$47,1,H$6) -> 8000000 | I15: =INDEX(Revenue!$D$47:$H$47,1,I$5)*INDEX(Assumptions!$B$47:$M$47,1,I$6) -> 4800000 | ... BI15: =INDEX(Revenue!$D$47:$H$47,1,BI$5)*INDEX(Assumptions!$B$47:$M$47,1,BI$6) -> 0
A16: Advisory | B16: =INDEX(Revenue!$D$48:$H$48,1,B$5)*INDEX(Assumptions!$B$48:$M$48,1,B$6) -> 600000 | C16: =INDEX(Revenue!$D$48:$H$48,1,C$5)*INDEX(Assumptions!$B$48:$M$48,1,C$6) -> 1200000 | D16: =INDEX(Revenue!$D$48:$H$48,1,D$5)*INDEX(Assumptions!$B$48:$M$48,1,D$6) -> 2400000 | E16: =INDEX(Revenue!$D$48:$H$48,1,E$5)*INDEX(Assumptions!$B$48:$M$48,1,E$6) -> 3000000 | F16: =INDEX(Revenue!$D$48:$H$48,1,F$5)*INDEX(Assumptions!$B$48:$M$48,1,F$6) -> 3000000 | G16: =INDEX(Revenue!$D$48:$H$48,1,G$5)*INDEX(Assumptions!$B$48:$M$48,1,G$6) -> 3000000 | H16: =INDEX(Revenue!$D$48:$H$48,1,H$5)*INDEX(Assumptions!$B$48:$M$48,1,H$6) -> 2400000 | I16: =INDEX(Revenue!$D$48:$H$48,1,I$5)*INDEX(Assumptions!$B$48:$M$48,1,I$6) -> 2400000 | ... BI16: =INDEX(Revenue!$D$48:$H$48,1,BI$5)*INDEX(Assumptions!$B$48:$M$48,1,BI$6) -> 20400000
A17: Data products | B17: =INDEX(Revenue!$D$49:$H$49,1,B$5)*INDEX(Assumptions!$B$49:$M$49,1,B$6) -> 0 | C17: =INDEX(Revenue!$D$49:$H$49,1,C$5)*INDEX(Assumptions!$B$49:$M$49,1,C$6) -> 0 | D17: =INDEX(Revenue!$D$49:$H$49,1,D$5)*INDEX(Assumptions!$B$49:$M$49,1,D$6) -> 0 | E17: =INDEX(Revenue!$D$49:$H$49,1,E$5)*INDEX(Assumptions!$B$49:$M$49,1,E$6) -> 0 | F17: =INDEX(Revenue!$D$49:$H$49,1,F$5)*INDEX(Assumptions!$B$49:$M$49,1,F$6) -> 0 | G17: =INDEX(Revenue!$D$49:$H$49,1,G$5)*INDEX(Assumptions!$B$49:$M$49,1,G$6) -> 0 | H17: =INDEX(Revenue!$D$49:$H$49,1,H$5)*INDEX(Assumptions!$B$49:$M$49,1,H$6) -> 0 | I17: =INDEX(Revenue!$D$49:$H$49,1,I$5)*INDEX(Assumptions!$B$49:$M$49,1,I$6) -> 0 | ... BI17: =INDEX(Revenue!$D$49:$H$49,1,BI$5)*INDEX(Assumptions!$B$49:$M$49,1,BI$6) -> 10560000
A18: Platform services | B18: =INDEX(Revenue!$D$50:$H$50,1,B$5)*INDEX(Assumptions!$B$50:$M$50,1,B$6) -> 0 | C18: =INDEX(Revenue!$D$50:$H$50,1,C$5)*INDEX(Assumptions!$B$50:$M$50,1,C$6) -> 0 | D18: =INDEX(Revenue!$D$50:$H$50,1,D$5)*INDEX(Assumptions!$B$50:$M$50,1,D$6) -> 0 | E18: =INDEX(Revenue!$D$50:$H$50,1,E$5)*INDEX(Assumptions!$B$50:$M$50,1,E$6) -> 0 | F18: =INDEX(Revenue!$D$50:$H$50,1,F$5)*INDEX(Assumptions!$B$50:$M$50,1,F$6) -> 0 | G18: =INDEX(Revenue!$D$50:$H$50,1,G$5)*INDEX(Assumptions!$B$50:$M$50,1,G$6) -> 0 | H18: =INDEX(Revenue!$D$50:$H$50,1,H$5)*INDEX(Assumptions!$B$50:$M$50,1,H$6) -> 0 | I18: =INDEX(Revenue!$D$50:$H$50,1,I$5)*INDEX(Assumptions!$B$50:$M$50,1,I$6) -> 0 | ... BI18: =INDEX(Revenue!$D$50:$H$50,1,BI$5)*INDEX(Assumptions!$B$50:$M$50,1,BI$6) -> 6000000
A19: Total revenue | B19: =SUM(B9:B18) -> 16322500 | C19: =SUM(C9:C18) -> 26827500 | D19: =SUM(D9:D18) -> 20510000 | E19: =SUM(E9:E18) -> 19612500 | F19: =SUM(F9:F18) -> 20792500 | G19: =SUM(G9:G18) -> 20293750 | H19: =SUM(H9:H18) -> 29313750 | I19: =SUM(I9:I18) -> 18513750 | ... BI19: =SUM(BI9:BI18) -> 149355000
A20: Receipts and payments
A21: Cash received | B21: =IF(B$4-Assumptions!$C$34<1,0,INDEX($B$19:$BI$19,1,B$4-Assumptions!$C$34)) -> 0 | C21: =IF(C$4-Assumptions!$C$34<1,0,INDEX($B$19:$BI$19,1,C$4-Assumptions!$C$34)) -> 16322500 | D21: =IF(D$4-Assumptions!$C$34<1,0,INDEX($B$19:$BI$19,1,D$4-Assumptions!$C$34)) -> 26827500 | E21: =IF(E$4-Assumptions!$C$34<1,0,INDEX($B$19:$BI$19,1,E$4-Assumptions!$C$34)) -> 20510000 | F21: =IF(F$4-Assumptions!$C$34<1,0,INDEX($B$19:$BI$19,1,F$4-Assumptions!$C$34)) -> 19612500 | G21: =IF(G$4-Assumptions!$C$34<1,0,INDEX($B$19:$BI$19,1,G$4-Assumptions!$C$34)) -> 20792500 | H21: =IF(H$4-Assumptions!$C$34<1,0,INDEX($B$19:$BI$19,1,H$4-Assumptions!$C$34)) -> 20293750 | I21: =IF(I$4-Assumptions!$C$34<1,0,INDEX($B$19:$BI$19,1,I$4-Assumptions!$C$34)) -> 29313750 | ... BI21: =IF(BI$4-Assumptions!$C$34<1,0,INDEX($B$19:$BI$19,1,BI$4-Assumptions!$C$34)) -> 206877500
A22: Delivery costs | B22: =-(INDEX(Costs!$C$5:$G$5,1,B$5)*INDEX(Assumptions!$B$43:$M$43,1,B$6)+INDEX(Costs!$C$6:$G$6,1,B$5)*INDEX(Assumptions!$B$44:$M$44,1,B$6)+INDEX(Costs!$C$7:$G$7,1,B$5)*INDEX(Assumptions!$B$47:$M$47,1,B$6)+INDEX(Costs!$C$8:$G$8,1,B$5)*INDEX(Assumptions!$B$48:$M$48,1,B$6)+INDEX(Costs!$C$9:$G$9,1,B$5)*INDEX(Assumptions!$B$45:$M$45,1,B$6)) -> -536000 | C22: =-(INDEX(Costs!$C$5:$G$5,1,C$5)*INDEX(Assumptions!$B$43:$M$43,1,C$6)+INDEX(Costs!$C$6:$G$6,1,C$5)*INDEX(Assumptions!$B$44:$M$44,1,C$6)+INDEX(Costs!$C$7:$G$7,1,C$5)*INDEX(Assumptions!$B$47:$M$47,1,C$6)+INDEX(Costs!$C$8:$G$8,1,C$5)*INDEX(Assumptions!$B$48:$M$48,1,C$6)+INDEX(Costs!$C$9:$G$9,1,C$5)*INDEX(Assumptions!$B$45:$M$45,1,C$6)) -> -1811000 | D22: =-(INDEX(Costs!$C$5:$G$5,1,D$5)*INDEX(Assumptions!$B$43:$M$43,1,D$6)+INDEX(Costs!$C$6:$G$6,1,D$5)*INDEX(Assumptions!$B$44:$M$44,1,D$6)+INDEX(Costs!$C$7:$G$7,1,D$5)*INDEX(Assumptions!$B$47:$M$47,1,D$6)+INDEX(Costs!$C$8:$G$8,1,D$5)*INDEX(Assumptions!$B$48:$M$48,1,D$6)+INDEX(Costs!$C$9:$G$9,1,D$5)*INDEX(Assumptions!$B$45:$M$45,1,D$6)) -> -4724000 | E22: =-(INDEX(Costs!$C$5:$G$5,1,E$5)*INDEX(Assumptions!$B$43:$M$43,1,E$6)+INDEX(Costs!$C$6:$G$6,1,E$5)*INDEX(Assumptions!$B$44:$M$44,1,E$6)+INDEX(Costs!$C$7:$G$7,1,E$5)*INDEX(Assumptions!$B$47:$M$47,1,E$6)+INDEX(Costs!$C$8:$G$8,1,E$5)*INDEX(Assumptions!$B$48:$M$48,1,E$6)+INDEX(Costs!$C$9:$G$9,1,E$5)*INDEX(Assumptions!$B$45:$M$45,1,E$6)) -> -5866000 | F22: =-(INDEX(Costs!$C$5:$G$5,1,F$5)*INDEX(Assumptions!$B$43:$M$43,1,F$6)+INDEX(Costs!$C$6:$G$6,1,F$5)*INDEX(Assumptions!$B$44:$M$44,1,F$6)+INDEX(Costs!$C$7:$G$7,1,F$5)*INDEX(Assumptions!$B$47:$M$47,1,F$6)+INDEX(Costs!$C$8:$G$8,1,F$5)*INDEX(Assumptions!$B$48:$M$48,1,F$6)+INDEX(Costs!$C$9:$G$9,1,F$5)*INDEX(Assumptions!$B$45:$M$45,1,F$6)) -> -6415000 | G22: =-(INDEX(Costs!$C$5:$G$5,1,G$5)*INDEX(Assumptions!$B$43:$M$43,1,G$6)+INDEX(Costs!$C$6:$G$6,1,G$5)*INDEX(Assumptions!$B$44:$M$44,1,G$6)+INDEX(Costs!$C$7:$G$7,1,G$5)*INDEX(Assumptions!$B$47:$M$47,1,G$6)+INDEX(Costs!$C$8:$G$8,1,G$5)*INDEX(Assumptions!$B$48:$M$48,1,G$6)+INDEX(Costs!$C$9:$G$9,1,G$5)*INDEX(Assumptions!$B$45:$M$45,1,G$6)) -> -6751000 | H22: =-(INDEX(Costs!$C$5:$G$5,1,H$5)*INDEX(Assumptions!$B$43:$M$43,1,H$6)+INDEX(Costs!$C$6:$G$6,1,H$5)*INDEX(Assumptions!$B$44:$M$44,1,H$6)+INDEX(Costs!$C$7:$G$7,1,H$5)*INDEX(Assumptions!$B$47:$M$47,1,H$6)+INDEX(Costs!$C$8:$G$8,1,H$5)*INDEX(Assumptions!$B$48:$M$48,1,H$6)+INDEX(Costs!$C$9:$G$9,1,H$5)*INDEX(Assumptions!$B$45:$M$45,1,H$6)) -> -6684000 | I22: =-(INDEX(Costs!$C$5:$G$5,1,I$5)*INDEX(Assumptions!$B$43:$M$43,1,I$6)+INDEX(Costs!$C$6:$G$6,1,I$5)*INDEX(Assumptions!$B$44:$M$44,1,I$6)+INDEX(Costs!$C$7:$G$7,1,I$5)*INDEX(Assumptions!$B$47:$M$47,1,I$6)+INDEX(Costs!$C$8:$G$8,1,I$5)*INDEX(Assumptions!$B$48:$M$48,1,I$6)+INDEX(Costs!$C$9:$G$9,1,I$5)*INDEX(Assumptions!$B$45:$M$45,1,I$6)) -> -5932000 | ... BI22: =-(INDEX(Costs!$C$5:$G$5,1,BI$5)*INDEX(Assumptions!$B$43:$M$43,1,BI$6)+INDEX(Costs!$C$6:$G$6,1,BI$5)*INDEX(Assumptions!$B$44:$M$44,1,BI$6)+INDEX(Costs!$C$7:$G$7,1,BI$5)*INDEX(Assumptions!$B$47:$M$47,1,BI$6)+INDEX(Costs!$C$8:$G$8,1,BI$5)*INDEX(Assumptions!$B$48:$M$48,1,BI$6)+INDEX(Costs!$C$9:$G$9,1,BI$5)*INDEX(Assumptions!$B$45:$M$45,1,BI$6)) -> -24894000
A23: Personnel and overheads | B23: =-(INDEX(Costs!$C$17:$G$17,1,B$5)-INDEX(Costs!$C$18:$G$18,1,B$5))/12 -> -18012438 | C23: =-(INDEX(Costs!$C$17:$G$17,1,C$5)-INDEX(Costs!$C$18:$G$18,1,C$5))/12 -> -18012438 | D23: =-(INDEX(Costs!$C$17:$G$17,1,D$5)-INDEX(Costs!$C$18:$G$18,1,D$5))/12 -> -18012438 | E23: =-(INDEX(Costs!$C$17:$G$17,1,E$5)-INDEX(Costs!$C$18:$G$18,1,E$5))/12 -> -18012438 | F23: =-(INDEX(Costs!$C$17:$G$17,1,F$5)-INDEX(Costs!$C$18:$G$18,1,F$5))/12 -> -18012438 | G23: =-(INDEX(Costs!$C$17:$G$17,1,G$5)-INDEX(Costs!$C$18:$G$18,1,G$5))/12 -> -18012438 | H23: =-(INDEX(Costs!$C$17:$G$17,1,H$5)-INDEX(Costs!$C$18:$G$18,1,H$5))/12 -> -18012438 | I23: =-(INDEX(Costs!$C$17:$G$17,1,I$5)-INDEX(Costs!$C$18:$G$18,1,I$5))/12 -> -18012438 | ... BI23: =-(INDEX(Costs!$C$17:$G$17,1,BI$5)-INDEX(Costs!$C$18:$G$18,1,BI$5))/12 -> -89805292
A25: Net cash movement | B25: =B21+B22+B23 -> -18548438 | C25: =C21+C22+C23 -> -3500937.5 | D25: =D21+D22+D23 -> 4091062.5 | E25: =E21+E22+E23 -> -3368437.5 | F25: =F21+F22+F23 -> -4814937.5 | G25: =G21+G22+G23 -> -3970937.5 | H25: =H21+H22+H23 -> -4402687.5 | I25: =I21+I22+I23 -> 5369312.5 | ... BI25: =BI21+BI22+BI23 -> 92178208
A26: Opening cash | B26: =Assumptions!$C$33 -> 0 | C26: =B27 -> -18548438 | D26: =C27 -> -22049375 | E26: =D27 -> -17958312 | F26: =E27 -> -21326750 | G26: =F27 -> -26141688 | H26: =G27 -> -30112625 | I26: =H27 -> -34515312 | J26: =I27 -> -29146000 | ... BI26: =BH27 -> 1.7072398e+09
A27: Closing cash | B27: =B26+B25 -> -18548438 | C27: =C26+C25 -> -22049375 | D27: =D26+D25 -> -17958312 | E27: =E26+E25 -> -21326750 | F27: =F26+F25 -> -26141688 | G27: =G26+G25 -> -30112625 | H27: =H26+H25 -> -34515312 | I27: =I26+I25 -> -29146000 | ... BI27: =BI26+BI25 -> 1799418000
A29: What this says
A30: Lowest cumulative cash | B30: =MIN($B$27:$BI$27) -> -62687646 | D30: Working capital that must be in place before Month 1, if opening cash is zero.
A31: Month it occurs | B31: =MATCH(B30,$B$27:$BI$27,0) -> 13
A32: First month cash-positive | B32: =IFERROR(MATCH(TRUE(),INDEX($B$27:$BI$27>0,0),0),0) -> 27
A33: Year 1 cash collected | B33: =SUM($B$21:$M$21) -> 237962500
A34: Year 1 cash spent | B34: =-SUM($B$22:$M$22)-SUM($B$23:$M$23) -> 279899250

Sheet Unit Economics
A1: Unit economics by engine
A2: Measured at Year 3, once each engine is running. Acquisition cost and renewal are inputs; the rest follow.
A3: Engine | B3: Units (Y3) | C3: Revenue (Y3) | D3: Average contract value | E3: Gross margin | F3: Acquisition cost | G3: Annual renewal | H3: Lifetime value | I3: Payback (months) | J3: Recurring?
A4: Membership | B4: =Customers!L4+Customers!L5+Customers!L6+Customers!L7+Customers!L8+Customers!L9 -> 861 | C4: =Revenue!F$41 -> 220625000 | D4: =IF(B4=0,0,C4/B4) -> 256242.74 | E4: =IF(C4=0,0,1) -> 1 | F4: 120000 | G4: 0.78 | H4: =IF(G4>=1,0,D4*E4/(1-G4)) -> 1164739.7 | I4: =IF(D4*E4=0,0,F4/(D4*E4/12)) -> 5.6196714 | J4: Yes
A5: Strategic partnerships | B5: =Customers!L10+Customers!L11+Customers!L12 -> 21 | C5: =Revenue!F$42 -> 117000000 | D5: =IF(B5=0,0,C5/B5) -> 5571428.6 | E5: =IF(C5=0,0,1) -> 1 | F5: 2500000 | G5: 0.7 | H5: =IF(G5>=1,0,D5*E5/(1-G5)) -> 18571429 | I5: =IF(D5*E5=0,0,F5/(D5*E5/12)) -> 5.3846154 | J5: Partly
A6: Professional education | B6: =Customers!L13+Customers!L14+Customers!L15 -> 142 | C6: =Revenue!F$43 -> 188000000 | D6: =IF(B6=0,0,C6/B6) -> 1323943.7 | E6: =IF(C6=0,0,1-Costs!E$5/C6) -> 0.66 | F6: 180000 | G6: 0.25 | H6: =IF(G6>=1,0,D6*E6/(1-G6)) -> 1165070.4 | I6: =IF(D6*E6=0,0,F6/(D6*E6/12)) -> 2.4719536 | J6: No
A7: Certification | B7: =Customers!L16+Customers!L17+Customers!L18 -> 116 | C7: =Revenue!F$44 -> 47850000 | D7: =IF(B7=0,0,C7/B7) -> 412500 | E7: =IF(C7=0,0,1-Costs!E$6/C7) -> 0.7 | F7: 90000 | G7: 0.8 | H7: =IF(G7>=1,0,D7*E7/(1-G7)) -> 1443750 | I7: =IF(D7*E7=0,0,F7/(D7*E7/12)) -> 3.7402597 | J7: Yes (renewal)
A8: Research | B8: =Customers!L19+Customers!L20+Customers!L21 -> 34 | C8: =Revenue!F$45 -> 102000000 | D8: =IF(B8=0,0,C8/B8) -> 3000000 | E8: =IF(C8=0,0,1-Costs!E$9/C8) -> 0.69 | F8: 350000 | G8: 0.45 | H8: =IF(G8>=1,0,D8*E8/(1-G8)) -> 3763636.4 | I8: =IF(D8*E8=0,0,F8/(D8*E8/12)) -> 2.0289855 | J8: Partly
A9: Intelligence | B9: =Customers!L22+Customers!L23+Customers!L24+Customers!L25+Customers!L26 -> 127 | C9: =Revenue!F$46 -> 76000000 | D9: =IF(B9=0,0,C9/B9) -> 598425.2 | E9: =IF(C9=0,0,1) -> 1 | F9: 220000 | G9: 0.82 | H9: =IF(G9>=1,0,D9*E9/(1-G9)) -> 3324584.4 | I9: =IF(D9*E9=0,0,F9/(D9*E9/12)) -> 4.4115789 | J9: Yes
A10: Events | B10: =Customers!L27+Customers!L28+Customers!L29+Customers!L30 -> 617 | C10: =Revenue!F$47 -> 135000000 | D10: =IF(B10=0,0,C10/B10) -> 218800.65 | E10: =IF(C10=0,0,1-Costs!E$7/C10) -> 0.55 | F10: 35000 | G10: 0.55 | H10: =IF(G10>=1,0,D10*E10/(1-G10)) -> 267423.01 | I10: =IF(D10*E10=0,0,F10/(D10*E10/12)) -> 3.490101 | J10: No
A11: Advisory | B11: =Customers!L31+Customers!L32+Customers!L33 -> 14 | C11: =Revenue!F$48 -> 112000000 | D11: =IF(B11=0,0,C11/B11) -> 8000000 | E11: =IF(C11=0,0,1-Costs!E$8/C11) -> 0.56 | F11: 3500000 | G11: 0.35 | H11: =IF(G11>=1,0,D11*E11/(1-G11)) -> 6892307.7 | I11: =IF(D11*E11=0,0,F11/(D11*E11/12)) -> 9.375 | J11: No
A12: Data products | B12: =Customers!L34+Customers!L35+Customers!L36 -> 17 | C12: =Revenue!F$49 -> 34000000 | D12: =IF(B12=0,0,C12/B12) -> 2000000 | E12: =IF(C12=0,0,1) -> 1 | F12: 400000 | G12: 0.85 | H12: =IF(G12>=1,0,D12*E12/(1-G12)) -> 13333333 | I12: =IF(D12*E12=0,0,F12/(D12*E12/12)) -> 2.4 | J12: Yes
A13: Platform services | B13: =Customers!L37+Customers!L38 -> 112 | C13: =Revenue!F$50 -> 26500000 | D13: =IF(B13=0,0,C13/B13) -> 236607.14 | E13: =IF(C13=0,0,1) -> 1 | F13: 60000 | G13: 0.8 | H13: =IF(G13>=1,0,D13*E13/(1-G13)) -> 1183035.7 | I13: =IF(D13*E13=0,0,F13/(D13*E13/12)) -> 3.0430189 | J13: Yes
A16: Gross margin here is revenue less the delivery cost that scales with it. Engines with no delivery line — membership, partnerships, intelligence, data, platform — read 100%, which is true only in the sense that their cost sits in personnel and technology rather than in a per-unit charge.

Sheet Revenue Mix
A1: Revenue mix and concentration
A2: Share of revenue by engine, against the mature mix the specification sets in §39.
A3: Engine | B3: Year 1 | C3: Year 2 | D3: Year 3 | E3: Year 4 | F3: Year 5 | H3: §39 target (mature)
A4: Membership | B4: =IF(Revenue!D$52=0,0,Revenue!D$41/Revenue!D$52) -> 0.20040181 | C4: =IF(Revenue!E$52=0,0,Revenue!E$41/Revenue!E$52) -> 0.21728917 | D4: =IF(Revenue!F$52=0,0,Revenue!F$41/Revenue!F$52) -> 0.20833825 | E4: =IF(Revenue!G$52=0,0,Revenue!G$41/Revenue!G$52) -> 0.20926715 | F4: =IF(Revenue!H$52=0,0,Revenue!H$41/Revenue!H$52) -> 0.22116022 | I4: 20–25%
A5: Strategic partnerships | B5: =IF(Revenue!D$52=0,0,Revenue!D$42/Revenue!D$52) -> 0.20090407 | C5: =IF(Revenue!E$52=0,0,Revenue!E$42/Revenue!E$52) -> 0.12121212 | D5: =IF(Revenue!F$52=0,0,Revenue!F$42/Revenue!F$52) -> 0.11048419 | E5: =IF(Revenue!G$52=0,0,Revenue!G$42/Revenue!G$52) -> 0.089371649 | F5: =IF(Revenue!H$52=0,0,Revenue!H$42/Revenue!H$52) -> 0.077978613 | I5: 5–10%
A6: Professional education | B6: =IF(Revenue!D$52=0,0,Revenue!D$43/Revenue!D$52) -> 0.24108488 | C6: =IF(Revenue!E$52=0,0,Revenue!E$43/Revenue!E$52) -> 0.21799389 | D6: =IF(Revenue!F$52=0,0,Revenue!F$43/Revenue!F$52) -> 0.17753016 | E6: =IF(Revenue!G$52=0,0,Revenue!G$43/Revenue!G$52) -> 0.14079472 | F6: =IF(Revenue!H$52=0,0,Revenue!H$43/Revenue!H$52) -> 0.12870256 | I6: 15–20% with certification
A7: Certification | B7: =IF(Revenue!D$52=0,0,Revenue!D$44/Revenue!D$52) -> 0 | C7: =IF(Revenue!E$52=0,0,Revenue!E$44/Revenue!E$52) -> 0.033826638 | D7: =IF(Revenue!F$52=0,0,Revenue!F$44/Revenue!F$52) -> 0.045185203 | E7: =IF(Revenue!G$52=0,0,Revenue!G$44/Revenue!G$52) -> 0.050240616 | F7: =IF(Revenue!H$52=0,0,Revenue!H$44/Revenue!H$52) -> 0.055644932 | I7: (with education)
A8: Research | B8: =IF(Revenue!D$52=0,0,Revenue!D$45/Revenue!D$52) -> 0.076343546 | C8: =IF(Revenue!E$52=0,0,Revenue!E$45/Revenue!E$52) -> 0.084566596 | D8: =IF(Revenue!F$52=0,0,Revenue!F$45/Revenue!F$52) -> 0.096319554 | E8: =IF(Revenue!G$52=0,0,Revenue!G$45/Revenue!G$52) -> 0.092946515 | F8: =IF(Revenue!H$52=0,0,Revenue!H$45/Revenue!H$52) -> 0.094255702 | I8: 15–20% with intelligence
A9: Intelligence | B9: =IF(Revenue!D$52=0,0,Revenue!D$46/Revenue!D$52) -> 0 | C9: =IF(Revenue!E$52=0,0,Revenue!E$46/Revenue!E$52) -> 0.052619215 | D9: =IF(Revenue!F$52=0,0,Revenue!F$46/Revenue!F$52) -> 0.071767511 | E9: =IF(Revenue!G$52=0,0,Revenue!G$46/Revenue!G$52) -> 0.076722123 | F9: =IF(Revenue!H$52=0,0,Revenue!H$46/Revenue!H$52) -> 0.086117157 | I9: (with research)
A10: Events | B10: =IF(Revenue!D$52=0,0,Revenue!D$47/Revenue!D$52) -> 0.16072325 | C10: =IF(Revenue!E$52=0,0,Revenue!E$47/Revenue!E$52) -> 0.14188396 | D10: =IF(Revenue!F$52=0,0,Revenue!F$47/Revenue!F$52) -> 0.12748176 | E10: =IF(Revenue!G$52=0,0,Revenue!G$47/Revenue!G$52) -> 0.1225354 | F10: =IF(Revenue!H$52=0,0,Revenue!H$47/Revenue!H$52) -> 0.1290811 | I10: 10–15%
A11: Advisory | B11: =IF(Revenue!D$52=0,0,Revenue!D$48/Revenue!D$52) -> 0.12054244 | C11: =IF(Revenue!E$52=0,0,Revenue!E$48/Revenue!E$52) -> 0.10523843 | D11: =IF(Revenue!F$52=0,0,Revenue!F$48/Revenue!F$52) -> 0.10576265 | E11: =IF(Revenue!G$52=0,0,Revenue!G$48/Revenue!G$52) -> 0.14629451 | F11: =IF(Revenue!H$52=0,0,Revenue!H$48/Revenue!H$52) -> 0.12870256 | I11: 10–15%
A12: Data products | B12: =IF(Revenue!D$52=0,0,Revenue!D$49/Revenue!D$52) -> 0 | C12: =IF(Revenue!E$52=0,0,Revenue!E$49/Revenue!E$52) -> 0.011275546 | D12: =IF(Revenue!F$52=0,0,Revenue!F$49/Revenue!F$52) -> 0.032106518 | E12: =IF(Revenue!G$52=0,0,Revenue!G$49/Revenue!G$52) -> 0.044328338 | F12: =IF(Revenue!H$52=0,0,Revenue!H$49/Revenue!H$52) -> 0.049966878 | I12: 5–10% with platform
